Workbook

Sheet Dashboard
B2: EMPLOYEE PERFORMANCE DASHBOARD
B4: =CONCATENATE("Workforce of ",Summary!B10," employees across ",5," departments | Data as of ",TEXT(TODAY(),"dd-mmm-yyyy")) -> Workforce of 100 employees across 5 departments | Data as of 14-Jul-2026
B6: TOTAL EMPLOYEES | D6: AVG ATTENDANCE | F6: AVG RATING | H6: SALES ACHIEVEMENT | J6: AVG OVERTIME (HRS)
B7: =Summary!B10 -> 100 | D7: =Summary!C10 -> 0.9085 | F7: =Summary!D10 -> 4.077 | H7: =Summary!G10 -> 0.96761607 | J7: =Summary!K10 -> 9.25
H45: Top 10 Performers (by Rating)
H46: Name | I46: Dept. | J46: Rating | K46: Sales Achieved
H47: =Summary!B27 -> Karthik | I47: =Summary!C27 -> Finance | J47: =Summary!E27 -> 5 | K47: =Summary!F27 -> 966305
H48: =Summary!B28 -> Lavanya | I48: =Summary!C28 -> IT | J48: =Summary!E28 -> 5 | K48: =Summary!F28 -> 502542
H49: =Summary!B29 -> Sneha | I49: =Summary!C29 -> HR | J49: =Summary!E29 -> 5 | K49: =Summary!F29 -> 454685
H50: =Summary!B30 -> Asha | I50: =Summary!C30 -> Marketing | J50: =Summary!E30 -> 5 | K50: =Summary!F30 -> 682192
H51: =Summary!B31 -> Lavanya | I51: =Summary!C31 -> HR | J51: =Summary!E31 -> 4.9 | K51: =Summary!F31 -> 863509
H52: =Summary!B32 -> Lavanya | I52: =Summary!C32 -> Finance | J52: =Summary!E32 -> 4.9 | K52: =Summary!F32 -> 915692
H53: =Summary!B33 -> Divya | I53: =Summary!C33 -> Marketing | J53: =Summary!E33 -> 4.9 | K53: =Summary!F33 -> 451908
H54: =Summary!B34 -> Keerthi | I54: =Summary!C34 -> Finance | J54: =Summary!E34 -> 4.9 | K54: =Summary!F34 -> 570218
H55: =Summary!B35 -> Sanjay | I55: =Summary!C35 -> Sales | J55: =Summary!E35 -> 4.9 | K55: =Summary!F35 -> 956240
H56: =Summary!B36 -> Anu | I56: =Summary!C36 -> HR | J56: =Summary!E36 -> 4.9 | K56: =Summary!F36 -> 629883

Sheet Employee_Data
A1: Employee ID | B1: Employee Name | C1: Gender | D1: Department | E1: Designation | F1: Manager | G1: Joining Date | H1: Attendance % | I1: Working Days | J1: Leave Days | K1: Tasks Assigned | L1: Tasks Completed | M1: Sales Target | N1: Sales Achieved | O1: Rating | P1: Overtime
A2: E001 | B2: Anu | C2: Female | D2: HR | E2: Analyst | F2: Raj | G2: 44573 | H2: 86 | I2: 22 | J2: 3 | K2: 111 | L2: 76 | M2: 538186 | N2: 629883 | O2: 4.9 | P2: 8
A3: E002 | B3: Vijay | C3: Female | D3: Marketing | E3: Senior Analyst | F3: Anitha | G3: 44814 | H3: 91 | I3: 22 | J3: 1 | K3: 99 | L3: 86 | M3: 213332 | N3: 190623 | O3: 3.6 | P3: 6
A4: E003 | B4: Deepa | C4: Female | D4: HR | E4: Team Lead | F4: Raj | G4: 45977 | H4: 99 | I4: 22 | J4: 4 | K4: 158 | L4: 106 | M4: 675341 | N4: 726005 | O4: 3.3 | P4: 3
A5: E004 | B5: Manoj | C5: Female | D5: Finance | E5: Senior Analyst | F5: Kumar | G5: 45614 | H5: 95 | I5: 22 | J5: 1 | K5: 178 | L5: 171 | M5: 139924 | N5: 103437 | O5: 3.8 | P5: 11
A6: E005 | B6: Meena | C6: Female | D6: Marketing | E6: Analyst | F6: Kumar | G6: 44920 | H6: 89 | I6: 22 | J6: 3 | K6: 80 | L6: 68 | M6: 484244 | N6: 352867 | O6: 4.4 | P6: 3
A7: E006 | B7: Sanjay | C7: Female | D7: IT | E7: Senior Analyst | F7: Priya | G7: 44650 | H7: 99 | I7: 22 | J7: 3 | K7: 188 | L7: 125 | M7: 894667 | N7: 849496 | O7: 3.3 | P7: 1
A8: E007 | B8: Manoj | C8: Female | D8: Sales | E8: Senior Analyst | F8: Priya | G8: 45638 | H8: 81 | I8: 22 | J8: 4 | K8: 128 | L8: 112 | M8: 447755 | N8: 439703 | O8: 3.2 | P8: 9
A9: E008 | B9: Keerthi | C9: Female | D9: IT | E9: Executive | F9: Kumar | G9: 44853 | H9: 98 | I9: 22 | J9: 1 | K9: 168 | L9: 122 | M9: 511450 | N9: 562589 | O9: 4.1 | P9: 2
A10: E009 | B10: Surya | C10: Male | D10: IT | E10: Analyst | F10: Anitha | G10: 45586 | H10: 90 | I10: 22 | J10: 4 | K10: 69 | L10: 62 | M10: 218780 | N10: 180274 | O10: 3.7 | P10: 0
A11: E010 | B11: Keerthi | C11: Male | D11: IT | E11: Manager | F11: Raj | G11: 44568 | H11: 83 | I11: 22 | J11: 3 | K11: 106 | L11: 73 | M11: 409996 | N11: 318106 | O11: 3.6 | P11: 2
A12: E011 | B12: Lavanya | C12: Male | D12: IT | E12: Senior Analyst | F12: Anitha | G12: 45257 | H12: 98 | I12: 22 | J12: 0 | K12: 128 | L12: 109 | M12: 253324 | N12: 249688 | O12: 4.1 | P12: 2
A13: E012 | B13: Sanjay | C13: Male | D13: Finance | E13: Manager | F13: Kumar | G13: 45686 | H13: 91 | I13: 22 | J13: 1 | K13: 55 | L13: 47 | M13: 842705 | N13: 798035 | O13: 3.7 | P13: 8
... A101: E100 | B101: Surya | C101: Female | D101: Marketing | E101: Analyst | F101: Kumar | G101: 45100 | H101: 99 | I101: 22 | J101: 3 | K101: 87 | L101: 53 | M101: 495462 | N101: 531460 | O101: 4.1 | P101: 20

Sheet Summary
A1: Employee Performance Dashboard — Summary Data | N1: Helper: SortKey | O1: Helper: RowIdx
N2: =Employee_Data!O2+ROW()/1000000 -> 4.900002 | O2: 2
A3: Department Summary | N3: =Employee_Data!O3+ROW()/1000000 -> 3.600003 | O3: 3
A4: Department | B4: Headcount | C4: Avg Attendance % | D4: Avg Rating | E4: Total Sales Target | F4: Total Sales Achieved | G4: Achievement % | H4: Total Tasks Assigned | I4: Total Tasks Completed | J4: Completion % | K4: Avg Overtime (hrs) | N4: =Employee_Data!O4+ROW()/1000000 -> 3.300004 | O4: 4
A5: HR | B5: =COUNTIF(Employee_Data!$D$2:$D$101,A5) -> 23 | C5: =AVERAGEIF(Employee_Data!$D$2:$D$101,A5,Employee_Data!$H$2:$H$101)/100 -> 0.92652174 | D5: =AVERAGEIF(Employee_Data!$D$2:$D$101,A5,Employee_Data!$O$2:$O$101) -> 3.9130435 | E5: =SUMIF(Employee_Data!$D$2:$D$101,A5,Employee_Data!$M$2:$M$101) -> 12901840 | F5: =SUMIF(Employee_Data!$D$2:$D$101,A5,Employee_Data!$N$2:$N$101) -> 12539903 | G5: =IFERROR(F5/E5,0) -> 0.97194687 | H5: =SUMIF(Employee_Data!$D$2:$D$101,A5,Employee_Data!$K$2:$K$101) -> 2923 | I5: =SUMIF(Employee_Data!$D$2:$D$101,A5,Employee_Data!$L$2:$L$101) -> 2311 | J5: =IFERROR(I5/H5,0) -> 0.79062607 | K5: =AVERAGEIF(Employee_Data!$D$2:$D$101,A5,Employee_Data!$P$2:$P$101) -> 7.7391304 | N5: =Employee_Data!O5+ROW()/1000000 -> 3.800005 | O5: 5
A6: Finance | B6: =COUNTIF(Employee_Data!$D$2:$D$101,A6) -> 22 | C6: =AVERAGEIF(Employee_Data!$D$2:$D$101,A6,Employee_Data!$H$2:$H$101)/100 -> 0.89636364 | D6: =AVERAGEIF(Employee_Data!$D$2:$D$101,A6,Employee_Data!$O$2:$O$101) -> 4.1545455 | E6: =SUMIF(Employee_Data!$D$2:$D$101,A6,Employee_Data!$M$2:$M$101) -> 11208100 | F6: =SUMIF(Employee_Data!$D$2:$D$101,A6,Employee_Data!$N$2:$N$101) -> 11241743 | G6: =IFERROR(F6/E6,0) -> 1.0030017 | H6: =SUMIF(Employee_Data!$D$2:$D$101,A6,Employee_Data!$K$2:$K$101) -> 2494 | I6: =SUMIF(Employee_Data!$D$2:$D$101,A6,Employee_Data!$L$2:$L$101) -> 2189 | J6: =IFERROR(I6/H6,0) -> 0.8777065 | K6: =AVERAGEIF(Employee_Data!$D$2:$D$101,A6,Employee_Data!$P$2:$P$101) -> 8.8636364 | N6: =Employee_Data!O6+ROW()/1000000 -> 4.400006 | O6: 6
A7: Marketing | B7: =COUNTIF(Employee_Data!$D$2:$D$101,A7) -> 21 | C7: =AVERAGEIF(Employee_Data!$D$2:$D$101,A7,Employee_Data!$H$2:$H$101)/100 -> 0.92238095 | D7: =AVERAGEIF(Employee_Data!$D$2:$D$101,A7,Employee_Data!$O$2:$O$101) -> 4.0619048 | E7: =SUMIF(Employee_Data!$D$2:$D$101,A7,Employee_Data!$M$2:$M$101) -> 11409711 | F7: =SUMIF(Employee_Data!$D$2:$D$101,A7,Employee_Data!$N$2:$N$101) -> 10906653 | G7: =IFERROR(F7/E7,0) -> 0.95590966 | H7: =SUMIF(Employee_Data!$D$2:$D$101,A7,Employee_Data!$K$2:$K$101) -> 2846 | I7: =SUMIF(Employee_Data!$D$2:$D$101,A7,Employee_Data!$L$2:$L$101) -> 2236 | J7: =IFERROR(I7/H7,0) -> 0.78566409 | K7: =AVERAGEIF(Employee_Data!$D$2:$D$101,A7,Employee_Data!$P$2:$P$101) -> 9.2857143 | N7: =Employee_Data!O7+ROW()/1000000 -> 3.300007 | O7: 7
A8: Sales | B8: =COUNTIF(Employee_Data!$D$2:$D$101,A8) -> 18 | C8: =AVERAGEIF(Employee_Data!$D$2:$D$101,A8,Employee_Data!$H$2:$H$101)/100 -> 0.89055556 | D8: =AVERAGEIF(Employee_Data!$D$2:$D$101,A8,Employee_Data!$O$2:$O$101) -> 4.0666667 | E8: =SUMIF(Employee_Data!$D$2:$D$101,A8,Employee_Data!$M$2:$M$101) -> 10281919 | F8: =SUMIF(Employee_Data!$D$2:$D$101,A8,Employee_Data!$N$2:$N$101) -> 9890150 | G8: =IFERROR(F8/E8,0) -> 0.96189729 | H8: =SUMIF(Employee_Data!$D$2:$D$101,A8,Employee_Data!$K$2:$K$101) -> 2057 | I8: =SUMIF(Employee_Data!$D$2:$D$101,A8,Employee_Data!$L$2:$L$101) -> 1700 | J8: =IFERROR(I8/H8,0) -> 0.82644628 | K8: =AVERAGEIF(Employee_Data!$D$2:$D$101,A8,Employee_Data!$P$2:$P$101) -> 11.722222 | N8: =Employee_Data!O8+ROW()/1000000 -> 3.200008 | O8: 8
A9: IT | B9: =COUNTIF(Employee_Data!$D$2:$D$101,A9) -> 16 | C9: =AVERAGEIF(Employee_Data!$D$2:$D$101,A9,Employee_Data!$H$2:$H$101)/100 -> 0.90125 | D9: =AVERAGEIF(Employee_Data!$D$2:$D$101,A9,Employee_Data!$O$2:$O$101) -> 4.2375 | E9: =SUMIF(Employee_Data!$D$2:$D$101,A9,Employee_Data!$M$2:$M$101) -> 7720035 | F9: =SUMIF(Employee_Data!$D$2:$D$101,A9,Employee_Data!$N$2:$N$101) -> 7209916 | G9: =IFERROR(F9/E9,0) -> 0.93392271 | H9: =SUMIF(Employee_Data!$D$2:$D$101,A9,Employee_Data!$K$2:$K$101) -> 2135 | I9: =SUMIF(Employee_Data!$D$2:$D$101,A9,Employee_Data!$L$2:$L$101) -> 1613 | J9: =IFERROR(I9/H9,0) -> 0.75550351 | K9: =AVERAGEIF(Employee_Data!$D$2:$D$101,A9,Employee_Data!$P$2:$P$101) -> 9.125 | N9: =Employee_Data!O9+ROW()/1000000 -> 4.100009 | O9: 9
A10: TOTAL / OVERALL | B10: =SUM(B5:B9) -> 100 | C10: =AVERAGE(Employee_Data!$H$2:$H$101)/100 -> 0.9085 | D10: =AVERAGE(Employee_Data!$O$2:$O$101) -> 4.077 | E10: =SUM(E5:E9) -> 53521605 | F10: =SUM(F5:F9) -> 51788365 | G10: =IFERROR(F10/E10,0) -> 0.96761607 | H10: =SUM(H5:H9) -> 12455 | I10: =SUM(I5:I9) -> 10049 | J10: =IFERROR(I10/H10,0) -> 0.80682457 | K10: =AVERAGE(Employee_Data!$P$2:$P$101) -> 9.25 | N10: =Employee_Data!O10+ROW()/1000000 -> 3.70001 | O10: 10
N11: =Employee_Data!O11+ROW()/1000000 -> 3.600011 | O11: 11
A12: Gender Summary | N12: =Employee_Data!O12+ROW()/1000000 -> 4.100012 | O12: 12
A13: Gender | B13: Headcount | C13: Avg Attendance % | D13: Avg Rating | E13: Avg Sales Achieved | F13: Avg Overtime (hrs) | N13: =Employee_Data!O13+ROW()/1000000 -> 3.700013 | O13: 13
A14: Female | B14: =COUNTIF(Employee_Data!$C$2:$C$101,A14) -> 50 | C14: =AVERAGEIF(Employee_Data!$C$2:$C$101,A14,Employee_Data!$H$2:$H$101)/100 -> 0.9076 | D14: =AVERAGEIF(Employee_Data!$C$2:$C$101,A14,Employee_Data!$O$2:$O$101) -> 4.088 | E14: =AVERAGEIF(Employee_Data!$C$2:$C$101,A14,Employee_Data!$N$2:$N$101) -> 506244.52 | F14: =AVERAGEIF(Employee_Data!$C$2:$C$101,A14,Employee_Data!$P$2:$P$101) -> 9.7 | N14: =Employee_Data!O14+ROW()/1000000 -> 4.700014 | O14: 14
A15: Male | B15: =COUNTIF(Employee_Data!$C$2:$C$101,A15) -> 50 | C15: =AVERAGEIF(Employee_Data!$C$2:$C$101,A15,Employee_Data!$H$2:$H$101)/100 -> 0.9094 | D15: =AVERAGEIF(Employee_Data!$C$2:$C$101,A15,Employee_Data!$O$2:$O$101) -> 4.066 | E15: =AVERAGEIF(Employee_Data!$C$2:$C$101,A15,Employee_Data!$N$2:$N$101) -> 529522.78 | F15: =AVERAGEIF(Employee_Data!$C$2:$C$101,A15,Employee_Data!$P$2:$P$101) -> 8.8 | N15: =Employee_Data!O15+ROW()/1000000 -> 4.100015 | O15: 15
N16: =Employee_Data!O16+ROW()/1000000 -> 3.500016 | O16: 16
A17: Designation Summary | N17: =Employee_Data!O17+ROW()/1000000 -> 4.600017 | O17: 17
A18: Designation | B18: Headcount | C18: Avg Rating | D18: Avg Sales Achieved | E18: Avg Attendance % | N18: =Employee_Data!O18+ROW()/1000000 -> 3.300018 | O18: 18
A19: Team Lead | B19: =COUNTIF(Employee_Data!$E$2:$E$101,A19) -> 29 | C19: =AVERAGEIF(Employee_Data!$E$2:$E$101,A19,Employee_Data!$O$2:$O$101) -> 4.1655172 | D19: =AVERAGEIF(Employee_Data!$E$2:$E$101,A19,Employee_Data!$N$2:$N$101) -> 489561.83 | E19: =AVERAGEIF(Employee_Data!$E$2:$E$101,A19,Employee_Data!$H$2:$H$101)/100 -> 0.90931034 | N19: =Employee_Data!O19+ROW()/1000000 -> 3.900019 | O19: 19
A20: Analyst | B20: =COUNTIF(Employee_Data!$E$2:$E$101,A20) -> 23 | C20: =AVERAGEIF(Employee_Data!$E$2:$E$101,A20,Employee_Data!$O$2:$O$101) -> 4.0608696 | D20: =AVERAGEIF(Employee_Data!$E$2:$E$101,A20,Employee_Data!$N$2:$N$101) -> 584422.83 | E20: =AVERAGEIF(Employee_Data!$E$2:$E$101,A20,Employee_Data!$H$2:$H$101)/100 -> 0.90869565 | N20: =Employee_Data!O20+ROW()/1000000 -> 4.30002 | O20: 20
A21: Senior Analyst | B21: =COUNTIF(Employee_Data!$E$2:$E$101,A21) -> 21 | C21: =AVERAGEIF(Employee_Data!$E$2:$E$101,A21,Employee_Data!$O$2:$O$101) -> 3.952381 | D21: =AVERAGEIF(Employee_Data!$E$2:$E$101,A21,Employee_Data!$N$2:$N$101) -> 476546.67 | E21: =AVERAGEIF(Employee_Data!$E$2:$E$101,A21,Employee_Data!$H$2:$H$101)/100 -> 0.9047619 | N21: =Employee_Data!O21+ROW()/1000000 -> 3.300021 | O21: 21
A22: Manager | B22: =COUNTIF(Employee_Data!$E$2:$E$101,A22) -> 19 | C22: =AVERAGEIF(Employee_Data!$E$2:$E$101,A22,Employee_Data!$O$2:$O$101) -> 4.0578947 | D22: =AVERAGEIF(Employee_Data!$E$2:$E$101,A22,Employee_Data!$N$2:$N$101) -> 474877.16 | E22: =AVERAGEIF(Employee_Data!$E$2:$E$101,A22,Employee_Data!$H$2:$H$101)/100 -> 0.90315789 | N22: =Employee_Data!O22+ROW()/1000000 -> 4.400022 | O22: 22
A23: Executive | B23: =COUNTIF(Employee_Data!$E$2:$E$101,A23) -> 8 | C23: =AVERAGEIF(Employee_Data!$E$2:$E$101,A23,Employee_Data!$O$2:$O$101) -> 4.175 | D23: =AVERAGEIF(Employee_Data!$E$2:$E$101,A23,Employee_Data!$N$2:$N$101) -> 639900.12 | E23: =AVERAGEIF(Employee_Data!$E$2:$E$101,A23,Employee_Data!$H$2:$H$101)/100 -> 0.9275 | N23: =Employee_Data!O23+ROW()/1000000 -> 4.600023 | O23: 23
N24: =Employee_Data!O24+ROW()/1000000 -> 3.700024 | O24: 24
A25: Top 10 Performers (by Rating) | N25: =Employee_Data!O25+ROW()/1000000 -> 4.400025 | O25: 25
A26: Rank | B26: Employee Name | C26: Department | D26: Designation | E26: Rating | F26: Sales Achieved | N26: =Employee_Data!O26+ROW()/1000000 -> 4.800026 | O26: 26
A27: 1 | B27: =INDEX(Employee_Data!$B$2:$B$101,MATCH(LARGE($N$2:$N$101,1),$N$2:$N$101,0)) -> Karthik | C27: =INDEX(Employee_Data!$D$2:$D$101,MATCH(LARGE($N$2:$N$101,1),$N$2:$N$101,0)) -> Finance | D27: =INDEX(Employee_Data!$E$2:$E$101,MATCH(LARGE($N$2:$N$101,1),$N$2:$N$101,0)) -> Analyst | E27: =INDEX(Employee_Data!$O$2:$O$101,MATCH(LARGE($N$2:$N$101,1),$N$2:$N$101,0)) -> 5 | F27: =INDEX(Employee_Data!$N$2:$N$101,MATCH(LARGE($N$2:$N$101,1),$N$2:$N$101,0)) -> 966305 | N27: =Employee_Data!O27+ROW()/1000000 -> 3.900027 | O27: 27
A28: 2 | B28: =INDEX(Employee_Data!$B$2:$B$101,MATCH(LARGE($N$2:$N$101,2),$N$2:$N$101,0)) -> Lavanya | C28: =INDEX(Employee_Data!$D$2:$D$101,MATCH(LARGE($N$2:$N$101,2),$N$2:$N$101,0)) -> IT | D28: =INDEX(Employee_Data!$E$2:$E$101,MATCH(LARGE($N$2:$N$101,2),$N$2:$N$101,0)) -> Team Lead | E28: =INDEX(Employee_Data!$O$2:$O$101,MATCH(LARGE($N$2:$N$101,2),$N$2:$N$101,0)) -> 5 | F28: =INDEX(Employee_Data!$N$2:$N$101,MATCH(LARGE($N$2:$N$101,2),$N$2:$N$101,0)) -> 502542 | N28: =Employee_Data!O28+ROW()/1000000 -> 3.400028 | O28: 28
A29: 3 | B29: =INDEX(Employee_Data!$B$2:$B$101,MATCH(LARGE($N$2:$N$101,3),$N$2:$N$101,0)) -> Sneha | C29: =INDEX(Employee_Data!$D$2:$D$101,MATCH(LARGE($N$2:$N$101,3),$N$2:$N$101,0)) -> HR | D29: =INDEX(Employee_Data!$E$2:$E$101,MATCH(LARGE($N$2:$N$101,3),$N$2:$N$101,0)) -> Executive | E29: =INDEX(Employee_Data!$O$2:$O$101,MATCH(LARGE($N$2:$N$101,3),$N$2:$N$101,0)) -> 5 | F29: =INDEX(Employee_Data!$N$2:$N$101,MATCH(LARGE($N$2:$N$101,3),$N$2:$N$101,0)) -> 454685 | N29: =Employee_Data!O29+ROW()/1000000 -> 4.500029 | O29: 29
A30: 4 | B30: =INDEX(Employee_Data!$B$2:$B$101,MATCH(LARGE($N$2:$N$101,4),$N$2:$N$101,0)) -> Asha | C30: =INDEX(Employee_Data!$D$2:$D$101,MATCH(LARGE($N$2:$N$101,4),$N$2:$N$101,0)) -> Marketing | D30: =INDEX(Employee_Data!$E$2:$E$101,MATCH(LARGE($N$2:$N$101,4),$N$2:$N$101,0)) -> Manager | E30: =INDEX(Employee_Data!$O$2:$O$101,MATCH(LARGE($N$2:$N$101,4),$N$2:$N$101,0)) -> 5 | F30: =INDEX(Employee_Data!$N$2:$N$101,MATCH(LARGE($N$2:$N$101,4),$N$2:$N$101,0)) -> 682192 | N30: =Employee_Data!O30+ROW()/1000000 -> 3.00003 | O30: 30
A31: 5 | B31: =INDEX(Employee_Data!$B$2:$B$101,MATCH(LARGE($N$2:$N$101,5),$N$2:$N$101,0)) -> Lavanya | C31: =INDEX(Employee_Data!$D$2:$D$101,MATCH(LARGE($N$2:$N$101,5),$N$2:$N$101,0)) -> HR | D31: =INDEX(Employee_Data!$E$2:$E$101,MATCH(LARGE($N$2:$N$101,5),$N$2:$N$101,0)) -> Team Lead | E31: =INDEX(Employee_Data!$O$2:$O$101,MATCH(LARGE($N$2:$N$101,5),$N$2:$N$101,0)) -> 4.9 | F31: =INDEX(Employee_Data!$N$2:$N$101,MATCH(LARGE($N$2:$N$101,5),$N$2:$N$101,0)) -> 863509 | N31: =Employee_Data!O31+ROW()/1000000 -> 4.600031 | O31: 31
A32: 6 | B32: =INDEX(Employee_Data!$B$2:$B$101,MATCH(LARGE($N$2:$N$101,6),$N$2:$N$101,0)) -> Lavanya | C32: =INDEX(Employee_Data!$D$2:$D$101,MATCH(LARGE($N$2:$N$101,6),$N$2:$N$101,0)) -> Finance | D32: =INDEX(Employee_Data!$E$2:$E$101,MATCH(LARGE($N$2:$N$101,6),$N$2:$N$101,0)) -> Team Lead | E32: =INDEX(Employee_Data!$O$2:$O$101,MATCH(LARGE($N$2:$N$101,6),$N$2:$N$101,0)) -> 4.9 | F32: =INDEX(Employee_Data!$N$2:$N$101,MATCH(LARGE($N$2:$N$101,6),$N$2:$N$101,0)) -> 915692 | N32: =Employee_Data!O32+ROW()/1000000 -> 4.400032 | O32: 32
A33: 7 | B33: =INDEX(Employee_Data!$B$2:$B$101,MATCH(LARGE($N$2:$N$101,7),$N$2:$N$101,0)) -> Divya | C33: =INDEX(Employee_Data!$D$2:$D$101,MATCH(LARGE($N$2:$N$101,7),$N$2:$N$101,0)) -> Marketing | D33: =INDEX(Employee_Data!$E$2:$E$101,MATCH(LARGE($N$2:$N$101,7),$N$2:$N$101,0)) -> Team Lead | E33: =INDEX(Employee_Data!$O$2:$O$101,MATCH(LARGE($N$2:$N$101,7),$N$2:$N$101,0)) -> 4.9 | F33: =INDEX(Employee_Data!$N$2:$N$101,MATCH(LARGE($N$2:$N$101,7),$N$2:$N$101,0)) -> 451908 | N33: =Employee_Data!O33+ROW()/1000000 -> 4.400033 | O33: 33
A34: 8 | B34: =INDEX(Employee_Data!$B$2:$B$101,MATCH(LARGE($N$2:$N$101,8),$N$2:$N$101,0)) -> Keerthi | C34: =INDEX(Employee_Data!$D$2:$D$101,MATCH(LARGE($N$2:$N$101,8),$N$2:$N$101,0)) -> Finance | D34: =INDEX(Employee_Data!$E$2:$E$101,MATCH(LARGE($N$2:$N$101,8),$N$2:$N$101,0)) -> Team Lead | E34: =INDEX(Employee_Data!$O$2:$O$101,MATCH(LARGE($N$2:$N$101,8),$N$2:$N$101,0)) -> 4.9 | F34: =INDEX(Employee_Data!$N$2:$N$101,MATCH(LARGE($N$2:$N$101,8),$N$2:$N$101,0)) -> 570218 | N34: =Employee_Data!O34+ROW()/1000000 -> 4.600034 | O34: 34
A35: 9 | B35: =INDEX(Employee_Data!$B$2:$B$101,MATCH(LARGE($N$2:$N$101,9),$N$2:$N$101,0)) -> Sanjay | C35: =INDEX(Employee_Data!$D$2:$D$101,MATCH(LARGE($N$2:$N$101,9),$N$2:$N$101,0)) -> Sales | D35: =INDEX(Employee_Data!$E$2:$E$101,MATCH(LARGE($N$2:$N$101,9),$N$2:$N$101,0)) -> Analyst | E35: =INDEX(Employee_Data!$O$2:$O$101,MATCH(LARGE($N$2:$N$101,9),$N$2:$N$101,0)) -> 4.9 | F35: =INDEX(Employee_Data!$N$2:$N$101,MATCH(LARGE($N$2:$N$101,9),$N$2:$N$101,0)) -> 956240 | N35: =Employee_Data!O35+ROW()/1000000 -> 3.200035 | O35: 35
A36: 10 | B36: =INDEX(Employee_Data!$B$2:$B$101,MATCH(LARGE($N$2:$N$101,10),$N$2:$N$101,0)) -> Anu | C36: =INDEX(Employee_Data!$D$2:$D$101,MATCH(LARGE($N$2:$N$101,10),$N$2:$N$101,0)) -> HR | D36: =INDEX(Employee_Data!$E$2:$E$101,MATCH(LARGE($N$2:$N$101,10),$N$2:$N$101,0)) -> Analyst | E36: =INDEX(Employee_Data!$O$2:$O$101,MATCH(LARGE($N$2:$N$101,10),$N$2:$N$101,0)) -> 4.9 | F36: =INDEX(Employee_Data!$N$2:$N$101,MATCH(LARGE($N$2:$N$101,10),$N$2:$N$101,0)) -> 629883 | N36: =Employee_Data!O36+ROW()/1000000 -> 4.500036 | O36: 36
N37: =Employee_Data!O37+ROW()/1000000 -> 3.500037 | O37: 37
N38: =Employee_Data!O38+ROW()/1000000 -> 4.700038 | O38: 38
N39: =Employee_Data!O39+ROW()/1000000 -> 3.400039 | O39: 39
N40: =Employee_Data!O40+ROW()/1000000 -> 4.80004 | O40: 40
...
